//The catch keyword indicates the catching of an exception.
/*using System;
using System.Collections.Generic;
using System.Linq;
using System.Text;
using System.Threading.Tasks;

namespace ConsoleApp2.OOPS_Problems
{
    internal class Class253
    {
        static void Main()
        {
            int num;
            Console.WriteLine("Enter number 1");
            num = Convert.ToInt32(Console.ReadLine());
            int n;
            Console.WriteLine("Enter number  2");
            n = Convert.ToInt32(Console.ReadLine());
            int res = 0;
            
            try
            {
                res = num / n; //error will come here and program terminates
            }
            catch (Exception ex)
            {
                Console.WriteLine("Number should not be devided by zero");
            }
            Console.WriteLine("Result=" + res);
            Console.WriteLine("Bye");
        }
    }
}*/
